<?xml version="1.0" ?>
<!-- =================================================================================== -->
<!-- |    This document was autogenerated by xacro from 3R.urdf.xacro                  | -->
<!-- |    EDITING THIS FILE BY HAND IS NOT RECOMMENDED                                 | -->
<!-- =================================================================================== -->
<robot name="robot">
  <material name="black">
    <color rgba="0.0 0.0 0.0 1.0"/>
  </material>
  <material name="blue">
    <color rgba="0.0 0.0 0.8 1.0"/>
  </material>
  <material name="green">
    <color rgba="0.0 0.8 0.0 1.0"/>
  </material>
  <material name="grey">
    <color rgba="0.2 0.2 0.2 1.0"/>
  </material>
  <material name="orange">
    <color rgba="1.0 0.4235294117647059 0.0392156862745098 1.0"/>
  </material>
  <material name="brown">
    <color rgba="0.8705882352941177 0.8117647058823529 0.7647058823529411 1.0"/>
  </material>
  <material name="red">
    <color rgba="0.8 0.0 0.0 1.0"/>
  </material>
  <material name="white">
    <color rgba="1.0 1.0 1.0 1.0"/>
  </material>
  <link name="link_0">
    <visual>
      <geometry>
        <box size="0.1 0.02 0.02"/>
      </geometry>
      <origin rpy="0 0 0" xyz="0.05 0 0"/>
      <material name="red"/>
    </visual>
    <collision>
      <geometry>
        <box size="0.1 0.02 0.02"/>
      </geometry>
      <origin rpy="0 0 0" xyz="0.05 0 0"/>
    </collision>
    <inertial>
      <origin rpy="0 0 0" xyz="0.05 0 0"/>
      <mass value="1"/>
      <inertia ixx="6.666666666666667e-05" ixy="0.0" ixz="0.0" iyy="0.0008666666666666667" iyz="0.0" izz="0.0008666666666666667"/>
    </inertial>
  </link>
  <link name="link_1">
    <visual>
      <geometry>
        <box size="0.1 0.02 0.02"/>
      </geometry>
      <origin rpy="0 0 0" xyz="0.05 0 0"/>
      <material name="green"/>
    </visual>
    <collision>
      <geometry>
        <box size="0.1 0.02 0.02"/>
      </geometry>
      <origin rpy="0 0 0" xyz="0.05 0 0"/>
    </collision>
    <inertial>
      <origin rpy="0 0 0" xyz="0.05 0 0"/>
      <mass value="1"/>
      <inertia ixx="6.666666666666667e-05" ixy="0.0" ixz="0.0" iyy="0.0008666666666666667" iyz="0.0" izz="0.0008666666666666667"/>
    </inertial>
  </link>
  <link name="link_2">
    <visual>
      <geometry>
        <box size="0.1 0.02 0.02"/>
      </geometry>
      <origin rpy="0 0 0" xyz="0.05 0 0"/>
      <material name="blue"/>
    </visual>
    <collision>
      <geometry>
        <box size="0.1 0.02 0.02"/>
      </geometry>
      <origin rpy="0 0 0" xyz="0.05 0 0"/>
    </collision>
    <inertial>
      <origin rpy="0 0 0" xyz="0.05 0 0"/>
      <mass value="1"/>
      <inertia ixx="6.666666666666667e-05" ixy="0.0" ixz="0.0" iyy="0.0008666666666666667" iyz="0.0" izz="0.0008666666666666667"/>
    </inertial>
  </link>
  <joint name="joint_1" type="continuous">
    <parent link="link_0"/>
    <child link="link_1"/>
    <origin rpy="0 0 0" xyz="0.1 0 0"/>
    <axis xyz="0 0 1"/>
  </joint>
  <joint name="joint_2" type="continuous">
    <parent link="link_1"/>
    <child link="link_2"/>
    <origin rpy="0 0 0" xyz="0.1 0 0"/>
    <axis xyz="0 0 1"/>
  </joint>
</robot>
<!--parse file : rosrun xacro xacro inorder -o 3R.urdf 3R.urdf.xacro-->
